<?xml version="1.0" encoding="utf-8"?>
<!-- =================================================================================== -->
<!-- |    This document was autogenerated by xacro from mars_lite_with_gripper.urdf.xacro | -->
<!-- |    EDITING THIS FILE BY HAND IS NOT RECOMMENDED                                 | -->
<!-- =================================================================================== -->
<robot name="mars_lite">
  <material name="blue">
    <color rgba="0 0 0.8 1"/>
  </material>
  <material name="black">
    <color rgba="0 0 0 1"/>
  </material>
  <material name="white">
    <color rgba="1 1 1 1"/>
  </material>
  <material name="lightgrey">
    <color rgba="0.7 0.7 0.7 1.0"/>
  </material>
  <!-- Base Link -->
  <link name="base_link">
    <visual>
      <origin rpy="0 0 0" xyz="0 0 0"/>
      <geometry>
        <mesh filename="package://mars_lite_description/meshes/mob_plat.dae"/>
      </geometry>
    </visual>
    <collision>
      <origin rpy="0 0 0" xyz="0.075 0 0.185"/>
      <geometry>
        <box size="0.78 0.51 0.37"/>
      </geometry>
    </collision>
  </link>
  <link name="right_wheel">
    <visual>
      <origin rpy="0 0 0" xyz="0 0 0"/>
      <geometry>
        <mesh filename="package://mars_lite_description/meshes/wheel.dae"/>
      </geometry>
    </visual>
    <collision>
      <origin rpy="1.57079632679 0 0" xyz="0 0 0"/>
      <geometry>
        <cylinder length="0.03" radius="0.1016"/>
      </geometry>
    </collision>
    <inertial>
      <mass value="1"/>
      <inertia ixx="1.0" ixy="0.0" ixz="0.0" iyy="1.0" iyz="0.0" izz="1.0"/>
    </inertial>
  </link>
  <joint name="right_wheel" type="continuous">
    <axis rpy="0 0 0" xyz="0 1 0"/>
    <parent link="base_link"/>
    <child link="right_wheel"/>
    <origin rpy="0 0 0" xyz="0 -0.1965 0"/>
  </joint>
  <link name="left_wheel">
    <visual>
      <origin rpy="0 0 0" xyz="0 0 0"/>
      <geometry>
        <mesh filename="package://mars_lite_description/meshes/wheel.dae"/>
      </geometry>
    </visual>
    <collision>
      <origin rpy="1.57079632679 0 0" xyz="0 0 0"/>
      <geometry>
        <cylinder length="0.03" radius="0.1016"/>
      </geometry>
    </collision>
    <inertial>
      <mass value="1"/>
      <inertia ixx="1.0" ixy="0.0" ixz="0.0" iyy="1.0" iyz="0.0" izz="1.0"/>
    </inertial>
  </link>
  <joint name="left_wheel" type="continuous">
    <axis rpy="0 0 0" xyz="0 1 0"/>
    <parent link="base_link"/>
    <child link="left_wheel"/>
    <origin rpy="0 0 0" xyz="0 0.1965 0"/>
  </joint>
  <!-- Mass parameters -->
  <!--xacro:property name="pi" value="3.14159265" /-->
  <transmission name="tm_shoulder_1_trans">
    <type>transmission_interface/SimpleTransmission</type>
    <joint name="tm_shoulder_1_joint">
      <hardwareInterface>PositionJointInterface</hardwareInterface>
    </joint>
    <actuator name="tm_shoulder_1_motor">
      <mechanicalReduction>1</mechanicalReduction>
    </actuator>
  </transmission>
  <transmission name="tm_shoulder_2_trans">
    <type>transmission_interface/SimpleTransmission</type>
    <joint name="tm_shoulder_2_joint">
      <hardwareInterface>PositionJointInterface</hardwareInterface>
    </joint>
    <actuator name="tm_shoulder_2_motor">
      <mechanicalReduction>1</mechanicalReduction>
    </actuator>
  </transmission>
  <transmission name="tm_elbow_1_trans">
    <type>transmission_interface/SimpleTransmission</type>
    <joint name="tm_elbow_1_joint">
      <hardwareInterface>PositionJointInterface</hardwareInterface>
    </joint>
    <actuator name="tm_elbow_1_motor">
      <mechanicalReduction>1</mechanicalReduction>
    </actuator>
  </transmission>
  <transmission name="tm_wrist_1_trans">
    <type>transmission_interface/SimpleTransmission</type>
    <joint name="tm_wrist_1_joint">
      <hardwareInterface>PositionJointInterface</hardwareInterface>
    </joint>
    <actuator name="tm_wrist_1_motor">
      <mechanicalReduction>1</mechanicalReduction>
    </actuator>
  </transmission>
  <transmission name="tm_wrist_2_trans">
    <type>transmission_interface/SimpleTransmission</type>
    <joint name="tm_wrist_2_joint">
      <hardwareInterface>PositionJointInterface</hardwareInterface>
    </joint>
    <actuator name="tm_wrist_2_motor">
      <mechanicalReduction>1</mechanicalReduction>
    </actuator>
  </transmission>
  <transmission name="tm_wrist_3_trans">
    <type>transmission_interface/SimpleTransmission</type>
    <joint name="tm_wrist_3_joint">
      <hardwareInterface>PositionJointInterface</hardwareInterface>
    </joint>
    <actuator name="tm_wrist_3_motor">
      <mechanicalReduction>1</mechanicalReduction>
    </actuator>
  </transmission>
  <link name="tm_base_link">
    <visual>
      <geometry>
        <mesh filename="package://tm_description/meshes/tm700/visual/Base.dae"/>
      </geometry>
    </visual>
    <collision>
      <geometry>
        <mesh filename="package://tm_description/meshes/tm700/collision/base.STL"/>
      </geometry>
    </collision>
    <inertial>
      <mass value="1.0"/>
      <origin rpy="0 0 0" xyz="0.0 0.0 0.0"/>
      <inertia ixx="0.00110833289" ixy="0.0" ixz="0.0" iyy="0.00110833289" iyz="0.0" izz="0.0018"/>
    </inertial>
  </link>
  <link name="tm_shoulder_1_link">
    <visual>
      <geometry>
        <mesh filename="package://tm_description/meshes/tm700/visual/Shoulder1.dae"/>
      </geometry>
    </visual>
    <collision>
      <geometry>
        <mesh filename="package://tm_description/meshes/tm700/collision/shoulder_1.STL"/>
      </geometry>
    </collision>
    <inertial>
      <mass value="4.5"/>
      <origin rpy="0 0 0" xyz="0.0 0.0 0.0"/>
      <inertia ixx="0.012487495005" ixy="0.0" ixz="0.0" iyy="0.012487495005" iyz="0.0" izz="0.0081"/>
    </inertial>
  </link>
  <joint name="tm_shoulder_1_joint" type="revolute">
    <parent link="tm_base_link"/>
    <child link="tm_shoulder_1_link"/>
    <origin rpy="-1.57079632679 0.0 0.0" xyz="0.0 0.0 0.1451"/>
    <axis xyz="0 -1 0"/>
    <limit effort="150.0" lower="-3.14159265359" upper="3.14159265359" velocity="3.15"/>
    <dynamics damping="0.0" friction="0.0"/>
  </joint>
  <link name="tm_arm_1_link">
    <visual>
      <geometry>
        <mesh filename="package://tm_description/meshes/tm700/visual/Arm1.dae"/>
      </geometry>
      <material name="DarkOlive">
        <color rgba="0.3 0.3 0.25 1.0"/>
      </material>
    </visual>
    <collision>
      <geometry>
        <mesh filename="package://tm_description/meshes/tm700/collision/arm_1.STL"/>
      </geometry>
    </collision>
    <inertial>
      <mass value="10.5"/>
      <origin rpy="0 0 0" xyz="0.0 0.0 0.28"/>
      <inertia ixx="0.28384988646" ixy="0.0" ixz="0.0" iyy="0.28384988646" iyz="0.0" izz="0.0189"/>
    </inertial>
  </link>
  <joint name="tm_shoulder_2_joint" type="revolute">
    <parent link="tm_shoulder_1_link"/>
    <child link="tm_arm_1_link"/>
    <origin rpy="0.0 0.0 -1.57079632679" xyz="0.0 0.0 -0.146"/>
    <axis xyz="0 0 1"/>
    <limit effort="150.0" lower="-3.14159265359" upper="3.14159265359" velocity="3.15"/>
    <dynamics damping="0.0" friction="0.0"/>
  </joint>
  <link name="tm_arm_2_link">
    <visual>
      <geometry>
        <mesh filename="package://tm_description/meshes/tm700/visual/Arm2.dae"/>
      </geometry>
    </visual>
    <collision>
      <geometry>
        <mesh filename="package://tm_description/meshes/tm700/collision/arm_2.STL"/>
      </geometry>
    </collision>
    <inertial>
      <mass value="2.1"/>
      <origin rpy="0 0 0" xyz="0.0 0.0 0.25"/>
      <inertia ixx="0.045639981744" ixy="0.0" ixz="0.0" iyy="0.045639981744" iyz="0.0" izz="0.00378"/>
    </inertial>
  </link>
  <joint name="tm_elbow_1_joint" type="revolute">
    <parent link="tm_arm_1_link"/>
    <child link="tm_arm_2_link"/>
    <origin rpy="0.0 0.0 0.0" xyz="0.329 0.0 0.1298"/>
    <axis xyz="0 0 1"/>
    <limit effort="150.0" lower="-3.14159265359" upper="3.14159265359" velocity="3.15"/>
    <dynamics damping="0.0" friction="0.0"/>
  </joint>
  <link name="tm_wrist_1_link">
    <visual>
      <geometry>
        <mesh filename="package://tm_description/meshes/tm700/visual/Wrist1.dae"/>
      </geometry>
    </visual>
    <collision>
      <geometry>
        <mesh filename="package://tm_description/meshes/tm700/collision/wrist_1.STL"/>
      </geometry>
    </collision>
    <inertial>
      <mass value="1.45"/>
      <origin rpy="0 0 0" xyz="0.0 0.0 0.0"/>
      <inertia ixx="0.132239947104" ixy="0.0" ixz="0.0" iyy="0.132239947104" iyz="0.0" izz="0.261"/>
    </inertial>
  </link>
  <joint name="tm_wrist_1_joint" type="revolute">
    <parent link="tm_arm_2_link"/>
    <child link="tm_wrist_1_link"/>
    <origin rpy="1.57079632679 0.0 1.57079632679" xyz="0.3115 0.0 -0.106"/>
    <axis xyz="0 1 0"/>
    <limit effort="28.0" lower="-3.14159265359" upper="3.14159265359" velocity="3.2"/>
    <dynamics damping="0.0" friction="0.0"/>
  </joint>
  <link name="tm_wrist_2_link">
    <visual>
      <geometry>
        <mesh filename="package://tm_description/meshes/tm700/visual/Wrist2.dae"/>
      </geometry>
      <material name="DarkOlive">
        <color rgba="0.3 0.3 0.25 1.0"/>
      </material>
    </visual>
    <collision>
      <geometry>
        <mesh filename="package://tm_description/meshes/tm700/collision/wrist_2.STL"/>
      </geometry>
    </collision>
    <inertial>
      <mass value="1.45"/>
      <origin rpy="0 0 0" xyz="0.0 0.0 0.0"/>
      <inertia ixx="0.132239947104" ixy="0.0" ixz="0.0" iyy="0.132239947104" iyz="0.0" izz="0.261"/>
    </inertial>
  </link>
  <joint name="tm_wrist_2_joint" type="revolute">
    <parent link="tm_wrist_1_link"/>
    <child link="tm_wrist_2_link"/>
    <origin rpy="1.57079632679 0.0 0.0" xyz="0.0 0.0 0.106"/>
    <axis xyz="0 1 0"/>
    <limit effort="28.0" lower="-3.14159265359" upper="3.14159265359" velocity="3.2"/>
    <dynamics damping="0.0" friction="0.0"/>
  </joint>
  <link name="tm_wrist_3_link">
    <visual>
      <geometry>
        <mesh filename="package://tm_description/meshes/tm700/visual/Wrist3.dae"/>
      </geometry>
      <origin rpy="0 0 0" xyz="0 0 0.015"/>
      <material name="Grey">
        <color rgba="0.5 0.5 0.5 1.0"/>
      </material>
    </visual>
    <collision>
      <geometry>
        <mesh filename="package://tm_description/meshes/tm700/collision/wrist_3.STL"/>
      </geometry>
    </collision>
    <inertial>
      <mass value="0.4"/>
      <origin rpy="0 0 0" xyz="0.0 0.0 0.0"/>
      <inertia ixx="0.036479985408" ixy="0.0" ixz="0.0" iyy="0.036479985408" iyz="0.0" izz="0.072"/>
    </inertial>
  </link>
  <joint name="tm_wrist_3_joint" type="revolute">
    <parent link="tm_wrist_2_link"/>
    <child link="tm_wrist_3_link"/>
    <origin rpy="0.0 0.0 0.0" xyz="0.0 0.0 0.0565"/>
    <axis xyz="0 0 1"/>
    <limit effort="28.0" lower="-3.14159265359" upper="3.14159265359" velocity="3.2"/>
    <dynamics damping="0.0" friction="0.0"/>
  </joint>
  <link name="tm_tip_link">
    <collision>
      <geometry>
        <box size="0.05 0.05 0.05"/>
      </geometry>
      <origin rpy="0 0 0" xyz="0 0 0.025"/>
    </collision>
  </link>
  <joint name="tm_tip_fixed_joint" type="fixed">
    <parent link="tm_wrist_3_link"/>
    <child link="tm_tip_link"/>
    <origin rpy="0.0 0.0 0.0" xyz="0.0 0.0 0.0579"/>
  </joint>
  <!-- ROS base to TM 'base_link' Coordinates transform -->
  <link name="tm_base"/>
  <joint name="tm_base-base_link" type="fixed">
    <origin rpy="0 0 0" xyz="0 0 0"/>
    <parent link="tm_base"/>
    <child link="tm_base_link"/>
  </joint>
  <!-- Frame coincident with all-zeros TCP on TM controller -->
  <link name="tm_tool0"/>
  <joint name="tm_tip_link-tool0" type="fixed">
    <parent link="tm_tip_link"/>
    <child link="tm_tool0"/>
    <origin rpy="0 0 0" xyz="0 0 0"/>
  </joint>
  <joint name="base_link_to_tm_base_link" type="fixed">
    <parent link="base_link"/>
    <child link="tm_base"/>
    <origin rpy="0.0 0.0 0.0" xyz="0.35 0.0 0.37"/>
  </joint>
  <!-- Frame for gripper TCP  -->
  <link name="tm_gripper"/>
  <joint name="tm_tip_link_to_tm_gripper" type="fixed">
    <parent link="tm_tip_link"/>
    <child link="tm_gripper"/>
    <origin rpy="0 0 0" xyz="0 0 0.1767"/>
  </joint>
  <!-- base -->
  <joint name="tm_tip_link_gripper_base_joint" type="fixed">
    <origin rpy="0 0 1.5708" xyz="0 0 0"/>
    <parent link="tm_tip_link"/>
    <child link="gripper_base"/>
  </joint>
  <link name="gripper_base">
    <!-- inertial>
				<mass value="0.1"/>
				<origin xyz="0 0 0.055"  />
				<cylinder_inertia radius="0.06" length="0.11" mass="0.1"/>
			</inertial -->
    <visual>
      <geometry>
        <mesh filename="package://robotiq_2f_model/model/meshes/2f85/visual/base.dae" scale="0.001 0.001 0.001"/>
      </geometry>
    </visual>
    <collision>
      <origin rpy="0 0 0" xyz="0 0 0.015"/>
      <geometry>
        <cylinder length="0.045" radius="0.04"/>
      </geometry>
    </collision>
    <collision>
      <origin rpy="0 0 0" xyz="0 0 0.06"/>
      <geometry>
        <box size="0.03 0.04 0.06"/>
      </geometry>
    </collision>
  </link>
  <!-- right finger -->
  <joint name="gripper_right_driver_joint" type="revolute">
    <origin rpy="0 0 0" xyz="0 0.0306011 0.054904"/>
    <parent link="gripper_base"/>
    <child link="gripper_right_driver"/>
    <axis xyz="1 0 0"/>
    <limit effort="60" lower="0.0" upper="0.872664444444" velocity="1.91986177778"/>
  </joint>
  <link name="gripper_right_driver">
    <!-- inertial>
				<mass value="0.1"/>
				<origin xyz="0 0 0.055"  />
				<cylinder_inertia radius="0.06" length="0.11" mass="0.1"/>
			</inertial -->
    <visual>
      <geometry>
        <mesh filename="package://robotiq_2f_model/model/meshes/2f85/visual/driver.dae" scale="0.001 0.001 0.001"/>
      </geometry>
    </visual>
    <collision>
      <origin rpy="-0.1 0 0" xyz="0 0.02 0"/>
      <geometry>
        <box size="0.02 0.04 0.02"/>
      </geometry>
    </collision>
  </link>
  <joint name="gripper_right_coupler_joint" type="fixed">
    <origin rpy="0 0 0" xyz="0 0.0315 -0.0041"/>
    <parent link="gripper_right_driver"/>
    <child link="gripper_right_coupler"/>
  </joint>
  <link name="gripper_right_coupler">
    <!-- inertial>
				<mass value="0.1"/>
				<origin xyz="0 0 0.055"  />
				<cylinder_inertia radius="0.06" length="0.11" mass="0.1"/>
			</inertial -->
    <visual>
      <geometry>
        <mesh filename="package://robotiq_2f_model/model/meshes/2f85/visual/coupler.dae" scale="0.001 0.001 0.001"/>
      </geometry>
    </visual>
    <collision>
      <origin rpy="-1.7 0 0" xyz="0 0.0 0.025"/>
      <geometry>
        <box size="0.03 0.065 0.02"/>
      </geometry>
    </collision>
  </link>
  <joint name="gripper_right_follower_joint" type="revolute">
    <origin rpy="0 0 0" xyz="0 0.0061 0.0471"/>
    <parent link="gripper_right_coupler"/>
    <child link="gripper_right_follower"/>
    <axis xyz="1 0 0"/>
    <limit effort="176" lower="-2.96705911111" upper="2.96705911111" velocity="1.91986177778"/>
    <mimic joint="gripper_right_driver_joint" multiplier="-1"/>
  </joint>
  <link name="gripper_right_follower">
    <visual>
      <geometry>
        <mesh filename="package://robotiq_2f_model/model/meshes/2f85/visual/follower.dae" scale="0.001 0.001 0.001"/>
      </geometry>
    </visual>
    <collision>
      <origin rpy="0 0 0" xyz="0 -0.018 0.022"/>
      <geometry>
        <box size="0.02 0.015 0.048"/>
      </geometry>
    </collision>
  </link>
  <joint name="gripper_right_pad_joint" type="fixed">
    <parent link="gripper_right_follower"/>
    <child link="gripper_right_pad"/>
  </joint>
  <link name="gripper_right_pad">
    <!-- inertial>
				<mass value="0.1"/>
				<origin xyz="0 0 0.055"  />
				<cylinder_inertia radius="0.06" length="0.11" mass="0.1"/>
			</inertial -->
    <visual>
      <geometry>
        <mesh filename="package://robotiq_2f_model/model/meshes/2f85/visual/pad.dae" scale="0.001 0.001 0.001"/>
      </geometry>
    </visual>
    <collision>
      <origin rpy="0 0 0" xyz="0 -0.022 0.031"/>
      <geometry>
        <box size="0.02 0.008 0.036"/>
      </geometry>
    </collision>
  </link>
  <joint name="gripper_right_spring_link_joint" type="revolute">
    <origin rpy="0 0 0" xyz="0 0.012 0.0614"/>
    <parent link="gripper_base"/>
    <child link="gripper_right_spring_link"/>
    <axis xyz="1 0 0"/>
    <limit effort="176" lower="-2.96705911111" upper="2.96705911111" velocity="1.91986177778"/>
    <mimic joint="gripper_right_driver_joint" multiplier="1"/>
  </joint>
  <link name="gripper_right_spring_link">
    <!-- inertial>
				<mass value="0.1"/>
				<origin xyz="0 0 0.055"  />
				<cylinder_inertia radius="0.06" length="0.11" mass="0.1"/>
			</inertial -->
    <visual>
      <geometry>
        <mesh filename="package://robotiq_2f_model/model/meshes/2f85/visual/spring_link.dae" scale="0.001 0.001 0.001"/>
      </geometry>
    </visual>
    <collision>
      <origin rpy="-0.7068 0 0" xyz="0 0.018 0.018"/>
      <geometry>
        <box size="0.04 0.02 0.065"/>
      </geometry>
    </collision>
  </link>
  <!-- left finger -->
  <joint name="gripper_left_driver_joint" type="revolute">
    <origin rpy="0 0 3.141592653589793" xyz="0 -0.0306011 0.054904"/>
    <parent link="gripper_base"/>
    <child link="gripper_left_driver"/>
    <axis xyz="1 0 0"/>
    <limit effort="176" lower="0.0" upper="0.715584844444" velocity="1.91986177778"/>
    <mimic joint="gripper_right_driver_joint" multiplier="1"/>
  </joint>
  <link name="gripper_left_driver">
    <!-- inertial>
				<mass value="0.1"/>
				<origin xyz="0 0 0.055"  />
				<cylinder_inertia radius="0.06" length="0.11" mass="0.1"/>
			</inertial -->
    <visual>
      <geometry>
        <mesh filename="package://robotiq_2f_model/model/meshes/2f85/visual/driver.dae" scale="0.001 0.001 0.001"/>
      </geometry>
    </visual>
    <collision>
      <origin rpy="-0.1 0 0" xyz="0 0.02 0"/>
      <geometry>
        <box size="0.02 0.04 0.02"/>
      </geometry>
    </collision>
  </link>
  <joint name="gripper_left_coupler_joint" type="fixed">
    <origin rpy="0 0 0" xyz="0 0.0315 -0.0041"/>
    <parent link="gripper_left_driver"/>
    <child link="gripper_left_coupler"/>
  </joint>
  <link name="gripper_left_coupler">
    <!-- inertial>
				<mass value="0.1"/>
				<origin xyz="0 0 0.055"  />
				<cylinder_inertia radius="0.06" length="0.11" mass="0.1"/>
			</inertial -->
    <visual>
      <geometry>
        <mesh filename="package://robotiq_2f_model/model/meshes/2f85/visual/coupler.dae" scale="0.001 0.001 0.001"/>
      </geometry>
    </visual>
    <collision>
      <origin rpy="-1.7 0 0" xyz="0 0.0 0.025"/>
      <geometry>
        <box size="0.03 0.065 0.02"/>
      </geometry>
    </collision>
  </link>
  <joint name="gripper_left_follower_joint" type="revolute">
    <origin rpy="0 0 0" xyz="0 0.0061 0.0471"/>
    <parent link="gripper_left_coupler"/>
    <child link="gripper_left_follower"/>
    <axis xyz="1 0 0"/>
    <limit effort="176" lower="-2.96705911111" upper="2.96705911111" velocity="1.91986177778"/>
    <mimic joint="gripper_right_driver_joint" multiplier="-1"/>
  </joint>
  <link name="gripper_left_follower">
    <visual>
      <geometry>
        <mesh filename="package://robotiq_2f_model/model/meshes/2f85/visual/follower.dae" scale="0.001 0.001 0.001"/>
      </geometry>
    </visual>
    <collision>
      <origin rpy="0 0 0" xyz="0 -0.018 0.022"/>
      <geometry>
        <box size="0.02 0.015 0.048"/>
      </geometry>
    </collision>
  </link>
  <joint name="gripper_left_pad_joint" type="fixed">
    <parent link="gripper_left_follower"/>
    <child link="gripper_left_pad"/>
  </joint>
  <link name="gripper_left_pad">
    <!-- inertial>
				<mass value="0.1"/>
				<origin xyz="0 0 0.055"  />
				<cylinder_inertia radius="0.06" length="0.11" mass="0.1"/>
			</inertial -->
    <visual>
      <geometry>
        <mesh filename="package://robotiq_2f_model/model/meshes/2f85/visual/pad.dae" scale="0.001 0.001 0.001"/>
      </geometry>
    </visual>
    <collision>
      <origin rpy="0 0 0" xyz="0 -0.022 0.031"/>
      <geometry>
        <box size="0.02 0.008 0.036"/>
      </geometry>
    </collision>
  </link>
  <joint name="gripper_left_spring_link_joint" type="revolute">
    <origin rpy="0 0 3.141592653589793" xyz="0 -0.012 0.0614"/>
    <parent link="gripper_base"/>
    <child link="gripper_left_spring_link"/>
    <axis xyz="1 0 0"/>
    <limit effort="176" lower="-2.96705911111" upper="2.96705911111" velocity="1.91986177778"/>
    <mimic joint="gripper_right_driver_joint" multiplier="1"/>
  </joint>
  <link name="gripper_left_spring_link">
    <!-- inertial>
				<mass value="0.1"/>
				<origin xyz="0 0 0.055"  />
				<cylinder_inertia radius="0.06" length="0.11" mass="0.1"/>
			</inertial -->
    <visual>
      <geometry>
        <mesh filename="package://robotiq_2f_model/model/meshes/2f85/visual/spring_link.dae" scale="0.001 0.001 0.001"/>
      </geometry>
    </visual>
    <collision>
      <origin rpy="-0.7068 0 0" xyz="0 0.018 0.018"/>
      <geometry>
        <box size="0.04 0.02 0.065"/>
      </geometry>
    </collision>
  </link>
  <transmission name="gripper_right_driver_trans">
    <type>transmission_interface/SimpleTransmission</type>
    <joint name="gripper_right_driver_joint">
      <hardwareInterface>hardware_interface/PositionJointInterface</hardwareInterface>
    </joint>
    <actuator name="gripper_right_driver_motor">
      <mechanicalReduction>1</mechanicalReduction>
    </actuator>
  </transmission>
</robot>

